Testing started at 11:39 ...
C:\Users\emile\Anaconda3\python.exe "C:\Program Files\JetBrains\PyCharm 2020.1\plugins\python\helpers\pycharm\_jb_pytest_runner.py" --path C:/Users/emile/Desktop/Github/src/test_cases.py
Launching pytest with arguments C:/Users/emile/Desktop/Github/src/test_cases.py in C:\Users\emile\Desktop\Github\src

============================= test session starts =============================
platform win32 -- Python 3.7.3, pytest-5.0.1, py-1.8.0, pluggy-0.12.0 -- C:\Users\emile\Anaconda3\python.exe
cachedir: .pytest_cache
rootdir: C:\Users\emile\Desktop\Github\src
plugins: arraydiff-0.3, doctestplus-0.3.0, openfiles-0.3.2, remotedata-0.3.1
collecting ... collected 3 items

test_cases.py::test_RPS PASSED                                           [ 33%]
test_cases.py::test_what_beats_2 FAILED                                  [ 66%]
test_cases.py:23 (test_what_beats_2)
3 != 0

Expected :0
Actual   :3
<Click to see difference>

def test_what_beats_2() -> None:
        """Test rps.what_beats(1)."""
>       assert rps.what_beats(2) == 0
E       assert 3 == 0

test_cases.py:26: AssertionError

test_cases.py::test_beats_0_2 FAILED                                     [100%]
test_cases.py:28 (test_beats_0_2)
def test_beats_0_2() -> None:
        """Test rps.beats(0, 2)."""
>       assert rps.what_beats(0, 2)
E       TypeError: what_beats() takes 1 positional argument but 2 were given

test_cases.py:31: TypeError


================================== FAILURES ===================================
______________________________ test_what_beats_2 ______________________________

    def test_what_beats_2() -> None:
        """Test rps.what_beats(1)."""
>       assert rps.what_beats(2) == 0
E       assert 3 == 0

test_cases.py:26: AssertionError
_______________________________ test_beats_0_2 ________________________________

    def test_beats_0_2() -> None:
        """Test rps.beats(0, 2)."""
>       assert rps.what_beats(0, 2)
E       TypeError: what_beats() takes 1 positional argument but 2 were given

test_cases.py:31: TypeError
===================== 2 failed, 1 passed in 0.13 seconds ======================

Process finished with exit code 1

Assertion failed

Assertion failed
